Workbook

Sheet MHP Emulator Emitter List
A1: EMITTER_ID | B1: EMITTER_NAME | C1: EMITTER_ID | D1: Amb EID | E1: AEX | F1: DESCRIPTION | G1: ELNOT | H1: SEGMENT_FUNCTION | I1: Threat Display | J1: Threat Priority | K1: Threat Tone | L1: FREQ_LOW | M1: FREQ_HIGH | N1: Freq Range (MHz) | O1: DeltaFreq | P1: FREQ_MOD | Q1: Freq Mod Parameters | R1: PRI_LOW | S1: PRI_HIGH | T1: PRI_Delta | U1: PRI_MOD | V1: PRI Mod Parameters | W1: PW_LOW | X1: PW_HIGH | Y1: PW_Delta | Z1: AZ_SCAN_PERIOD_MIN | AA1: AZ_SCAN_PERIOD_MAX | AB1: SCAN_MODULATION_TYPE | AC1: Dead Time x.xx | AD1: Az Sector Width xxx.x | AE1: Az Slew Rate x.xxxxx | AF1: TIMB xxxx.x | AG1: Az BW xx.x | AH1: El BW xx.x | AI1: Az Bar step xx.x | AJ1: Num Az Pos xxx.x | AK1: Signal BW xxx.x | AL1: ERP (dBm) | AM1: Ant Gain xx.x | AN1: 1st dwn xx.x | AO1: 1st Az Lobe Pos xxx.x | AP1: 2nd dwn xx.x | AQ1: 2nd Az Lobe Pos xxx.x | AR1: Num EL Pos xxx | AS1: El Sector Width xxx.x | AT1: El Slew Rate x.xxxxx | AU1: 1st Lobe Pos xxx.x | AV1: 2nd Lobe Pos xxx.x | AW1: Ant Pol x | AX1: AI x | AY1: Sq or Hex? x | AZ1: Scan Type x | BA1: Locate? x | BB1: MF x | BC1: RF Agile x | BD1: Pd x.xxxxx | BE1: Turn-on Range xxxx.xx | BF1: Bi-Dir Azimuth x | BG1: Bi-Dir Elevation x | BH1: AI Speed xxxxx.x | BI1: Weapons Range (miles) | BJ1: BeamWidth (deg) | BK1: ESM or ESM/RWR | BM1: S/S | BN1: TA | BO1: TT | BP1: TI | BQ1: mmW | BR1: Alert 1 | BS1: Alert 2 | BT1: Alert 3 | BU1: Alert 4 | BV1: 20 Amb | BW1: Notes | BX1: HTW (y/n) | BZ1: Emitter Type (Land, Sea, Air) (Random Assortment, see comment)
A2: 1 | B2: ="EMITTER_"&TEXT(A2,"00") -> EMITTER_01 | C2: 6 | D2: =A2*1000+E2 -> 1001 | E2: 1 | F2: SIMPLE HOSTILE MG | G2: ="Z00"&TEXT(A2,"0")&"Z" -> Z001Z | H2: GUIDANCE_ILLUMINATION | L2: 8000 | M2: 8100 | N2: =M2-L2 -> 100 | O2: =M2-L2 -> 100 | P2: TRIANGLE | Q2: Freq Range 20Mhz, duration 20 msec | R2: 0 | S2: 0 | T2: =S2-R2 -> 0 | U2: CW | W2: 0 | X2: 0 | Y2: =X2-W2 -> 0 | Z2: 0 | AA2: 0 | AB2: STEADY | AC2: 0 | AD2: 0 | AE2: 0 | AF2: 9999 | AG2: 5 | AH2: 5 | AI2: 0 | AJ2: 0 | AK2: 10 | AL2: 90 | AM2: 20 | AN2: 0 | AO2: 0 | AP2: 0 | AQ2: 0 | AR2: 0 | AS2: 0 | AT2: 0 | AU2: 0 | AV2: 0 | AW2: 2 | AX2: 1 | AY2: 0 | AZ2: 8 | BA2: 0 | BB2: 0 | BC2: 1 | BD2: 0.9 | BE2: =2*BI2 -> 40 | BF2: 0 | BG2: 0 | BH2: 700 | BI2: 20 | BJ2: 5 | BK2: ESM/RWR | BM2: 1 | BX2: y | BY2: 2 | BZ2: Airborne
A3: 1 | B3: ="EMITTER_"&TEXT(A3,"00") -> EMITTER_01 | C3: 6 | D3: =A3*1000+E3 -> 1002 | E3: 2 | F3: SIMPLE HOSTILE MG | G3: ="Z00"&TEXT(A3,"0")&"Z" -> Z001Z | H3: GUIDANCE_ILLUMINATION | L3: 8000 | M3: 8100 | N3: =M3-L3 -> 100 | O3: =M3-L3 -> 100 | P3: OOK | Q3: 500 msec ON 50 msec off | R3: 0 | S3: 0 | T3: =S3-R3 -> 0 | U3: CW | W3: 0 | X3: 0 | Y3: =X3-W3 -> 0 | Z3: 0 | AA3: 0 | AB3: STEADY | AC3: 50 | AD3: 0 | AE3: 0 | AF3: 500 | AG3: 10 | AH3: 10 | AI3: 0 | AJ3: 0 | AK3: 10 | AL3: 90 | AM3: 20 | AN3: 0 | AO3: 0 | AP3: 0 | AQ3: 0 | AR3: 0 | AS3: 0 | AT3: 0 | AU3: 0 | AV3: 0 | AW3: 2 | AX3: 1 | AY3: 0 | AZ3: 8 | BA3: 0 | BB3: 0 | BC3: 0 | BD3: 0.9 | BE3: =2*BI3 -> 40 | BF3: 0 | BG3: 0 | BH3: 700 | BI3: 20 | BJ3: 10 | BK3: ESM/RWR | BM3: 1 | BX3: y | BY3: 2 | BZ3: Airborne
A4: 2 | B4: ="EMITTER_"&TEXT(A4,"00") -> EMITTER_02 | C4: =5*A4 -> 10 | D4: =A4*1000+E4 -> 2001 | E4: 1 | F4: Simple HOSTILE TT Emitter | G4: ="Z00"&TEXT(A4,"0")&"Z" -> Z002Z | H4: TRACK | L4: 4600 | M4: 4650 | N4: =M4-L4 -> 50 | O4: =M4-L4 -> 50 | P4: Multibeam | Q4: Both frequencies on at the same time | R4: 580 | S4: 600 | T4: =S4-R4 -> 20 | U4: STAGGER | V4: 2 position stagger (580 600) | W4: 1 | X4: 2 | Y4: =X4-W4 -> 1 | Z4: 0 | AA4: 0 | AB4: STEADY | AC4: 0 | AD4: 0 | AE4: 0 | AF4: 9999 | AG4: 3 | AH4: 3 | AI4: 0 | AJ4: 0 | AK4: 0 | AL4: 120 | AM4: 20 | AN4: 0 | AO4: 0 | AP4: 0 | AQ4: 0 | AR4: 0 | AS4: 0 | AT4: 0 | AU4: 0 | AV4: 0 | AW4: 2 | AX4: 0 | AY4: 0 | AZ4: 8 | BA4: 1 | BB4: 1 | BC4: 0 | BD4: 0.9 | BE4: =2*BI4 -> 24 | BF4: 0 | BG4: 0 | BH4: 0 | BI4: 12 | BJ4: 3 | BK4: ESM/RWR | BO4: 1 | BR4: 1 | BX4: y | BY4: 4 | BZ4: Land
A5: 2 | B5: ="EMITTER_"&TEXT(A5,"00") -> EMITTER_02 | C5: =5*A5 -> 10 | D5: =A5*1000+E5 -> 2011 | E5: 11 | F5: Simple HOSTILE TT Emitter | G5: ="Z00"&TEXT(A5,"0")&"Z" -> Z002Z | H5: TRACK | L5: 9200 | M5: 9300 | N5: =M5-L5 -> 100 | O5: =M5-L5 -> 100 | P5: Multibeam | R5: 580 | S5: 600 | T5: =S5-R5 -> 20 | U5: STAGGER | V5: 2 position stagger (580 600) Sync wit F1 | W5: 1 | X5: 2 | Y5: =X5-W5 -> 1 | Z5: 0 | AA5: 0 | AB5: STEADY | AC5: 0 | AD5: 0 | AE5: 0 | AF5: 9999 | AG5: 3 | AH5: 3 | AI5: 0 | AJ5: 0 | AK5: 0 | AL5: 120 | AM5: 20 | AN5: 0 | AO5: 0 | AP5: 0 | AQ5: 0 | AR5: 0 | AS5: 0 | AT5: 0 | AU5: 0 | AV5: 0 | AW5: 2 | AX5: 0 | AY5: 0 | AZ5: 8 | BA5: 1 | BB5: 0 | BC5: 0 | BD5: 0.9 | BE5: =2*BI5 -> 24 | BF5: 0 | BG5: 0 | BH5: 0 | BI5: 12 | BJ5: 3 | BK5: ESM/RWR | BM5: 1 | BX5: y | BY5: 4 | BZ5: Land
A6: 3 | B6: ="EMITTER_"&TEXT(A6,"00") -> EMITTER_03 | C6: =5*A6 -> 15 | D6: =A6*1000+E6 -> 3001 | E6: 1 | F6: Simple HOSTILE TA/TT/MG Emitter - TA displayed | G6: ="Z00"&TEXT(A6,"0")&"Z" -> Z003Z | H6: SEARCH | L6: 9900 | M6: 9950 | N6: =M6-L6 -> 50 | O6: =M6-L6 -> 50 | P6: STABLE | R6: 20 | S6: 49 | T6: =S6-R6 -> 29 | U6: AGILE | V6: 3 PRI (20 31 49) Dwell for 400 258 163 pulses respectively) | W6: 10 | X6: 11 | Y6: =X6-W6 -> 1 | Z6: 2.9 | AA6: 2.9 | AB6: TRACK WHILE SCAL | AC6: 0 | AD6: 60 | AE6: 0 | AF6: 23.985 | AG6: 2 | AH6: 2 | AI6: 2 | AJ6: 30 | AK6: 0 | AL6: 92 | AM6: 20 | AN6: 0 | AO6: 0 | AP6: 0 | AQ6: 0 | AR6: 4 | AS6: 8 | AT6: 0 | AU6: 0 | AV6: 0 | AW6: 2 | AX6: 1 | AY6: 0 | AZ6: 4 | BA6: 0 | BB6: 0 | BC6: 0 | BD6: 0.9 | BE6: =2*BI6 -> 30 | BF6: 1 | BG6: 0 | BH6: 700 | BI6: 15 | BJ6: 2 | BK6: ESM/RWR | BM6: 1 | BX6: n | BY6: ="Approx "&TEXT((3*AA6),0)&" (3*SP)" -> Approx 9 (3*SP) | BZ6: Airborne
A7: 3 | B7: ="EMITTER_"&TEXT(A7,"00") -> EMITTER_03 | C7: =5*A7 -> 15 | D7: =A7*1000+E7 -> 3002 | E7: 2 | F7: Simple HOSTILE TA/TT/MG Emitter - TT displayed | G7: ="Z00"&TEXT(A7,"0")&"Z" -> Z003Z | H7: TRACK | L7: 9900 | M7: 9950 | N7: =M7-L7 -> 50 | O7: =M7-L7 -> 50 | P7: STABLE | R7: 20 | S7: 50 | T7: =S7-R7 -> 30 | U7: STABLE | W7: 1 | X7: 2 | Y7: =X7-W7 -> 1 | Z7: 0 | AA7: 0 | AB7: STEADY | AC7: 0 | AD7: 0 | AE7: 0 | AF7: 9999 | AG7: 2 | AH7: 2 | AI7: 0 | AJ7: 0 | AK7: 0 | AL7: 92 | AM7: 20 | AN7: 0 | AO7: 0 | AP7: 0 | AQ7: 0 | AR7: 0 | AS7: 0 | AT7: 0 | AU7: 0 | AV7: 0 | AW7: 2 | AX7: 1 | AY7: 0 | AZ7: 8 | BA7: 0 | BB7: 0 | BC7: 0 | BD7: 0.9 | BE7: =2*BI7 -> 30 | BF7: 0 | BG7: 0 | BH7: 700 | BI7: 15 | BJ7: 2 | BK7: ESM/RWR | BM7: 1 | BR7: 1 | BX7: y | BY7: 4 | BZ7: Airborne
A8: 3 | B8: ="EMITTER_"&TEXT(A8,"00") -> EMITTER_03 | C8: =5*A8 -> 15 | D8: =A8*1000+E8 -> 3003 | E8: 3 | F8: Simple HOSTILE TA/TT/MG Emitter - MG displayed | G8: ="Z00"&TEXT(A8,"0")&"Z" -> Z003Z | H8: GUIDANCE_ILLUMINATION | L8: 9900 | M8: 9950 | N8: =M8-L8 -> 50 | O8: =M8-L8 -> 50 | P8: STABLE | R8: 9 | S8: 72 | T8: =S8-R8 -> 63 | U8: STABLE | W8: 1 | X8: 5 | Y8: =X8-W8 -> 4 | Z8: 0 | AA8: 0 | AB8: STEADY | AC8: 0 | AD8: 0 | AE8: 0 | AF8: 9999 | AG8: 2 | AH8: 2 | AK8: 0 | AL8: 92 | AM8: 20 | AN8: 0 | AO8: 0 | AP8: 0 | AQ8: 0 | AR8: 0 | AS8: 0 | AT8: 0 | AU8: 0 | AV8: 0 | AW8: 2 | AX8: 1 | AY8: 0 | AZ8: 8 | BA8: 0 | BB8: 0 | BC8: 0 | BD8: 0.9 | BE8: =2*BI8 -> 30 | BF8: 0 | BG8: 0 | BH8: 700 | BI8: 15 | BJ8: 2 | BK8: ESM/RWR | BM8: 1 | BR8: 1 | BX8: y | BY8: 2 | BZ8: Airborne
A9: 4 | B9: ="EMITTER_"&TEXT(A9,"00") -> EMITTER_04 | C9: =5*A9 -> 20 | D9: =A9*1000+E9 -> 4001 | E9: 1 | F9: Simple HOSTILE S Emitter TA | G9: ="Z00"&TEXT(A9,"0")&"Z" -> Z004Z | H9: SEARCH | L9: 2200 | M9: 2250 | N9: =M9-L9 -> 50 | O9: =M9-L9 -> 50 | P9: STABLE | R9: 2000 | S9: 2400 | T9: =S9-R9 -> 400 | U9: STAGGER | V9: 2 Posn Stagger (2000 2400) | W9: 5 | X9: 7 | Y9: =X9-W9 -> 2 | Z9: 7 | AA9: 7 | AB9: MAB | AC9: 0 | AD9: 120 | AE9: 0 | AF9: 0 | AG9: 5 | AH9: 8 | AI9: 0 | AJ9: 0 | AK9: 0 | AL9: 120 | AM9: 25 | AN9: 0 | AO9: 0 | AP9: 0 | AQ9: 0 | AR9: 3 | AS9: 24 | AT9: 0 | AU9: 0 | AV9: 0 | AW9: 2 | AX9: 0 | AY9: 0 | AZ9: 7 | BA9: 1 | BB9: 0 | BC9: 0 | BD9: 0.9 | BE9: =2*BI9 -> 20 | BF9: 1 | BG9: 0 | BH9: 0 | BI9: 10 | BJ9: 5 | BK9: ESM/RWR | BP9: 1 | BR9: 1 | BS9: 1 | BX9: n | BY9: ="Approx "&TEXT((3*AA9),0)&" (3*SP)" -> Approx 21 (3*SP) | BZ9: Land
A10: 4 | B10: ="EMITTER_"&TEXT(A10,"00") -> EMITTER_04 | C10: =5*A10 -> 20 | D10: =A10*1000+E10 -> 4002 | E10: 2 | F10: Simple HOSTILE S Emitter TA | G10: ="Z00"&TEXT(A10,"0")&"Z" -> Z004Z | H10: SEARCH | L10: 2200 | M10: 2555 | N10: =M10-L10 -> 355 | O10: =M10-L10 -> 355 | P10: STABLE | R10: 2500 | S10: 2500 | T10: =S10-R10 -> 0 | U10: STABLE | W10: 5 | X10: 7 | Y10: =X10-W10 -> 2 | Z10: 7 | AA10: 7 | AB10: MAB | AC10: 0 | AD10: 120 | AE10: 0 | AF10: 0 | AG10: 5 | AH10: 8 | AI10: 0 | AJ10: 0 | AK10: 0 | AL10: 120 | AM10: 25 | AN10: 0 | AO10: 0 | AP10: 0 | AQ10: 0 | AR10: 3 | AS10: 24 | AT10: 0 | AU10: 0 | AV10: 0 | AW10: 2 | AX10: 0 | AY10: 0 | AZ10: 7 | BA10: 1 | BB10: 0 | BC10: 0 | BD10: 0.9 | BE10: =2*BI10 -> 20 | BF10: 1 | BG10: 0 | BH10: 0 | BI10: 10 | BJ10: 5 | BK10: ESM/RWR | BP10: 1 | BR10: 1 | BS10: 1 | BX10: n | BY10: ="Approx "&TEXT((3*AA10),0)&" (3*SP)" -> Approx 21 (3*SP) | BZ10: Land
A11: 5 | B11: ="EMITTER_"&TEXT(A11,"00") -> EMITTER_05 | C11: =5*A11 -> 25 | D11: =A11*1000+E11 -> 5001 | E11: 1 | F11: Simple HOSTILE EW Emitter | G11: ="Z00"&TEXT(A11,"0")&"Z" -> Z005Z | H11: EARLY_WARNING_GCI | L11: 1225 | M11: 1300 | N11: =M11-L11 -> 75 | O11: =M11-L11 -> 75 | P11: FMOP | Q11: Freq Range 10Mhz | R11: 1800 | S11: 2250 | T11: =S11-R11 -> 450 | U11: STAGGER | V11: 3 Posn Stagger (1800 2250 1954) | W11: 28 | X11: 29 | Y11: =X11-W11 -> 1 | Z11: 20 | AA11: 20 | AB11: MAU | AC11: 0 | AD11: 360 | AE11: 0 | AF11: 0 | AG11: 2 | AH11: 3 | AI11: 0 | AJ11: 0 | AK11: 10 | AL11: 100 | AM11: 20 | AN11: 0 | AO11: 0 | AP11: 0 | AQ11: 0 | AR11: 0 | AS11: 0 | AT11: 0 | AU11: 0 | AV11: 0 | AW11: 3 | AX11: 0 | AZ11: 0 | BA11: 1 | BD11: 0.9 | BE11: 30 | BF11: 0 | BG11: 0 | BH11: 0 | BI11: NA | BJ11: 2 | BK11: ESM | BO11: 1 | BR11: 1 | BX11: n | BY11: ="Approx "&TEXT((3*AA11),0)&" (3*SP)" -> Approx 60 (3*SP) | BZ11: Land
A12: 6 | B12: ="EMITTER_"&TEXT(A12,"00") -> EMITTER_06 | C12: =5*A12 -> 30 | D12: =A12*1000+E12 -> 6001 | E12: 1 | F12: Simple NEUTRAL S Emitter | G12: ="Z00"&TEXT(A12,"0")&"Z" -> Z006Z | H12: SEARCH | L12: 2500 | M12: 2550 | N12: =M12-L12 -> 50 | O12: =M12-L12 -> 50 | P12: STABLE | R12: 2500 | S12: 2550 | T12: =S12-R12 -> 50 | U12: STABLE | W12: 3 | X12: 5 | Y12: =X12-W12 -> 2 | Z12: 10 | AA12: 10 | AB12: MAU | AC12: 0 | AD12: 360 | AE12: 0 | AF12: 0 | AG12: 2 | AH12: 8 | AI12: 0 | AJ12: 0 | AK12: 0 | AL12: 110 | AM12: 20 | AN12: 0 | AO12: 0 | AP12: 0 | AQ12: 0 | AR12: 0 | AS12: 0 | AT12: 0 | AU12: 0 | AV12: 0 | AW12: 3 | AX12: 0 | AY12: 0 | AZ12: 0 | BA12: 1 | BB12: 1 | BC12: 0 | BD12: 0.9 | BE12: 30 | BF12: 0 | BG12: 0 | BH12: 0 | BI12: NA | BJ12: 2 | BK12: ESM | BM12: 1 | BX12: n | BY12: ="Approx "&TEXT((3*AA12),0)&" (3*SP)" -> Approx 30 (3*SP) | BZ12: Land
A13: 6 | B13: ="EMITTER_"&TEXT(A13,"00") -> EMITTER_06 | C13: =5*A13 -> 30 | D13: =A13*1000+E13 -> 6002 | E13: 2 | F13: Simple NEUTRAL S Emitter | G13: ="Z00"&TEXT(A13,"0")&"Z" -> Z006Z | H13: SEARCH | L13: 2700 | M13: 2749 | N13: =M13-L13 -> 49 | O13: =M13-L13 -> 49 | P13: AGILE | Q13: 4 Freq (2700 2722 2737 2749) Pulse to pulse Freq Agile | R13: 2500 | S13: 2550 | T13: =S13-R13 -> 50 | U13: STABLE | W13: 3 | X13: 5 | Y13: =X13-W13 -> 2 | Z13: 10 .5 | AA13: 10 .5 | AB13: MAU | AD13: 30 | AE13: 0 | AG13: 2 | AH13: 2 | AI13: 0 | AJ13: 0 | AK13: 0 | AL13: 110 | AM13: 20 | AN13: 0 | AO13: 0 | AP13: 0 | AQ13: 0 | AR13: 0 | AS13: 20 | AT13: 0 | AU13: 0 | AV13: 0 | AW13: 3 | AX13: 0 | AY13: 0 | AZ13: 5 | BA13: 1 | BB13: 1 | BC13: 1 | BD13: 0.9 | BE13: 30 | BF13: 0 | BG13: 0 | BH13: 0 | BI13: NA | BJ13: 5 | BK13: ESM | BM13: 1 | BX13: n | BY13: ="Approx "&TEXT(30,0)&" (3*SP)" -> Approx 30 (3*SP) | BZ13: Land
A14: 7 | B14: ="EMITTER_"&TEXT(A14,"00") -> EMITTER_07 | C14: =5*A14 -> 35 | D14: =A14*1000+E14 -> 7001 | E14: 1 | F14: Simple HOSTILE TT EMITTER | G14: ="Z00"&TEXT(A14,"0")&"Z" -> Z007Z | H14: TRACK | L14: 8000 | M14: 8050 | N14: =M14-L14 -> 50 | O14: =M14-L14 -> 50 | P14: SINUSOIDAL | Q14: Freq range 20MHz period 16 msec | R14: 0 | S14: 0 | T14: =S14-R14 -> 0 | U14: CW | W14: 0 | X14: 0 | Y14: =X14-W14 -> 0 | Z14: 0 | AA14: 0 | AB14: STEADY | AC14: 0 | AD14: 0 | AE14: 0 | AF14: 9999 | AG14: 5 | AH14: 5 | AI14: 0 | AJ14: =AD14/AG14 -> 0 | AK14: 20 | AL14: 95 | AM14: 20 | AN14: 0 | AO14: 0 | AP14: 0 | AQ14: 0 | AR14: 0 | AS14: 0 | AT14: 0 | AU14: 0 | AV14: 0 | AW14: 2 | AX14: 0 | AY14: 0 | AZ14: 8 | BA14: 1 | BB14: 0 | BC14: 1 | BD14: 0.9 | BE14: =2*BI14 -> 24 | BF14: 0 | BG14: 0 | BH14: 0 | BI14: 12 | BJ14: 5 | BK14: ESM/RWR | BM14: 1 | BX14: y | BY14: 4 | BZ14: Land
A15: 8 | B15: ="EMITTER_"&TEXT(A15,"00") -> EMITTER_08 | C15: =5*A15 -> 40 | D15: =A15*1000+E15 -> 8001 | E15: 1 | F15: Simple FRIENDLY TA Emitter | G15: ="Z00"&TEXT(A15,"0")&"Z" -> Z008Z | H15: SEARCH_ACQUISITION | L15: 5500 | M15: 5700 | N15: =M15-L15 -> 200 | O15: =M15-L15 -> 200 | P15: STABLE | R15: 450 | S15: 510 | T15: =S15-R15 -> 60 | U15: STAGGER | V15: 4 Posn Stagger (450 470 490 510) | W15: 1 | X15: 4 | Y15: =X15-W15 -> 3 | Z15: 4 | AA15: 4 | AB15: MAU | AC15: 0 | AD15: 360 | AE15: 0 | AF15: 0 | AG15: 3 | AH15: 3 | AI15: 0 | AJ15: 0 | AK15: 0 | AL15: 100 | AM15: 25 | AN15: 0 | AO15: 0 | AP15: 0 | AQ15: 0 | AR15: 0 | AS15: 0 | AT15: 0 | AU15: 0 | AV15: 0 | AW15: 2 | AX15: 0 | AY15: 0 | AZ15: 0 | BA15: 1 | BB15: 0 | BC15: 1 | BD15: 0.9 | BE15: 30 | BF15: 0 | BG15: 0 | BH15: 0 | BI15: NA | BJ15: 3 | BK15: ESM/RWR | BM15: 1 | BX15: n | BY15: ="Approx "&TEXT((2*AA15),0)&" (2*SP)" -> Approx 8 (2*SP) | BZ15: Land
A16: 8 | B16: ="EMITTER_"&TEXT(A16,"00") -> EMITTER_08 | C16: =5*A16 -> 40 | D16: =A16*1000+E16 -> 8002 | E16: 2 | F16: Simple FRIENDLY TA Emitter | G16: ="Z00"&TEXT(A16,"0")&"Z" -> Z008Z | H16: SEARCH_ACQUISITION | L16: 5700 | M16: 5800 | N16: =M16-L16 -> 100 | O16: =M16-L16 -> 100 | P16: STABLE | R16: 450 | S16: 510 | T16: =S16-R16 -> 60 | U16: STAGGER | V16: 4 Posn Stagger (450 470 490 510) | W16: 1 | X16: 4 | Y16: =X16-W16 -> 3 | Z16: 4 | AA16: 4 | AB16: MAU | AC16: 0 | AD16: 30 | AE16: 0 | AF16: 0 | AG16: 3 | AH16: 3 | AI16: 0 | AJ16: 0 | AK16: 0 | AL16: 100 | AM16: 25 | AN16: 0 | AO16: 0 | AP16: 0 | AQ16: 0 | AR16: 0 | AS16: 0 | AT16: 0 | AU16: 0 | AV16: 0 | AW16: 2 | AX16: 0 | AY16: 0 | AZ16: 0 | BA16: 1 | BB16: 0 | BC16: 1 | BD16: 0.9 | BE16: 30 | BF16: 0 | BG16: 0 | BH16: 0 | BI16: NA | BJ16: 3 | BK16: ESM/RWR | BM16: 1 | BX16: n | BY16: ="Approx "&TEXT((2*AA16),0)&" (2*SP)" -> Approx 8 (2*SP) | BZ16: Land
A17: 8 | B17: ="EMITTER_"&TEXT(A17,"00") -> EMITTER_08 | C17: =5*A17 -> 40 | D17: =A17*1000+E17 -> 8003 | E17: 3 | F17: Simple FRIENDLY TA Emitter | G17: ="Z00"&TEXT(A17,"0")&"Z" -> Z008Z | H17: TRACK | L17: 5810 | M17: 5900 | N17: =M17-L17 -> 90 | O17: =M17-L17 -> 90 | P17: STABLE | R17: 450 | S17: 510 | T17: =S17-R17 -> 60 | U17: STAGGER | V17: 4 Posn Stagger (450 470 490 510) | W17: 1 | X17: 4 | Y17: =X17-W17 -> 3 | Z17: 0 | AA17: 0 | AB17: STEADY | AC17: 0 | AD17: 0 | AE17: 0 | AF17: 0 | AG17: 3 | AH17: 3 | AI17: 0 | AJ17: 0 | AK17: 0 | AL17: 100 | AM17: 25 | AN17: 0 | AO17: 0 | AP17: 0 | AQ17: 0 | AR17: 0 | AS17: 0 | AT17: 0 | AU17: 0 | AV17: 0 | AW17: 2 | AX17: 0 | AY17: 0 | AZ17: 8 | BA17: 1 | BB17: 0 | BC17: 1 | BD17: 0.9 | BE17: 30 | BF17: 0 | BG17: 0 | BH17: 0 | BI17: NA | BJ17: 3 | BK17: ESM/RWR | BM17: 1 | BX17: n | BY17: 4 | BZ17: Land
A18: 9 | B18: ="EMITTER_"&TEXT(A18,"00") -> EMITTER_09 | C18: =5*A18 -> 45 | D18: =A18*1000+E18 -> 9001 | E18: 1 | F18: Simple HOSTILE TA/TT/MG Emitter - TA displayed | G18: ="Z10"&TEXT(A18,"0")&"A" -> Z109A | H18: SEARCH_ACQUISITION | L18: 7500 | M18: 8000 | N18: =M18-L18 -> 500 | O18: =M18-L18 -> 500 | P18: SINUSOIDAL | Q18: 500 MHz freq range 100 pulse sinusoid | R18: 250 | S18: 280 | T18: =S18-R18 -> 30 | U18: STAGGER | V18: 2 posn Stagger (250 280) | W18: 11 | X18: 15 | Y18: =X18-W18 -> 4 | Z18: 3.05 | AA18: 3.05 | AB18: RANDOM | AC18: 0 | AD18: 120 | AE18: 0 | AF18: 21.2 | AG18: 5 | AH18: 5 | AI18: 5 | AJ18: =AD18/AG18 -> 24 | AK18: 500 | AL18: 120 | AM18: 20 | AN18: 0 | AO18: 0 | AP18: 0 | AQ18: 0 | AR18: 6 | AS18: 30 | AT18: 0 | AU18: 0 | AV18: 0 | AW18: 2 | AX18: 0 | AY18: 0 | AZ18: 1 | BA18: 1 | BB18: 1 | BC18: 1 | BD18: 0.9 | BE18: =2*BI18 -> 28 | BF18: 0 | BG18: 0 | BH18: 0 | BI18: 14 | BJ18: 5 | BK18: ESM/RWR | BM18: 1 | BW18: Search mode, 1 of 2. T/G mode can be present at the same time. ESM to correlate to a single emitter. | BX18: n | BY18: ="Approx "&TEXT((2*AA18),0)&" (2*SP)" -> Approx 6 (2*SP) | BZ18: Sea
A19: 9 | B19: ="EMITTER_"&TEXT(A19,"00") -> EMITTER_09 | C19: =5*A19 -> 45 | D19: =A19*1000+E19 -> 9002 | E19: 2 | F19: Simple HOSTILE TA/TT/MG Emitter - TA displayed | G19: ="Z10"&TEXT(A19,"0")&"A" -> Z109A | H19: SEARCH_ACQUISITION | L19: 7500 | M19: 8000 | N19: =M19-L19 -> 500 | O19: =M19-L19 -> 500 | P19: SINUSOIDAL | Q19: 500 MHz freq range 100 pulse sinusoid | R19: 222 | S19: 233 | T19: =S19-R19 -> 11 | U19: STABLE | W19: 11 | X19: 15 | Y19: =X19-W19 -> 4 | Z19: 2.68 | AA19: 2.68 | AB19: RANDOM | AC19: 0 | AD19: 120 | AE19: 0 | AF19: 18.64 | AG19: 5 | AH19: 5 | AI19: 5 | AJ19: =AD19/AG19 -> 24 | AK19: 500 | AL19: 120 | AM19: 20 | AN19: 0 | AO19: 0 | AP19: 0 | AQ19: 0 | AR19: 6 | AS19: 30 | AT19: 0 | AU19: 0 | AV19: 0 | AW19: 2 | AX19: 0 | AY19: 0 | AZ19: 1 | BA19: 1 | BB19: 1 | BC19: 1 | BD19: 0.9 | BE19: =2*BI19 -> 28 | BF19: 0 | BG19: 0 | BH19: 0 | BI19: 14 | BJ19: 5 | BK19: ESM/RWR | BM19: 1 | BR19: 1 | BW19: Track antenna is separate from search_acq antenna. | BX19: y | BY19: 2 | BZ19: Sea
A20: 9 | B20: ="EMITTER_"&TEXT(A20,"00") -> EMITTER_09 | C20: =5*A20 -> 45 | D20: =A20*1000+E20 -> 9001 | E20: 1 | F20: Simple HOSTILE TA/TT/MG Emitter - TT/MG displayed | G20: ="Z110"&"A" -> Z110A | H20: TRACK_GUIDANCE | L20: 15000 | M20: 15240 | N20: =M20-L20 -> 240 | O20: =M20-L20 -> 240 | P20: STABLE | R20: 90 | S20: 100 | T20: =S20-R20 -> 10 | U20: STABLE | V20: Stable PRI with Doublets inserted between pulses. Az Cmd 3usec doublet, El Cmd 5usec doublet, in mid 80% of alternating PRI. | W20: 1 | X20: 2 | Y20: =X20-W20 -> 1 | Z20: 0 | AA20: 0 | AB20: STEADY | AC20: 0 | AD20: 0 | AE20: 0 | AF20: 9999 | AG20: 5 | AH20: 5 | AI20: 0 | AJ20: =AD20/AG20 -> 0 | AK20: 0 | AL20: 120 | AM20: 20 | AN20: 0 | AO20: 0 | AP20: 0 | AQ20: 0 | AR20: 0 | AS20: 0 | AT20: 0 | AU20: 0 | AV20: 0 | AW20: 2 | AX20: 0 | AY20: 0 | AZ20: 8 | BA20: 1 | BB20: 1 | BC20: 1 | BD20: 0.9 | BE20: =2*BI20 -> 28 | BF20: 0 | BG20: 0 | BH20: 0 | BI20: 14 | BJ20: 5 | BK20: ESM/RWR | BM20: 1 | BX20: n | BY20: ="Approx "&TEXT((2*AA20),0)&" (2*SP)" -> Approx 0 (2*SP) | BZ20: Sea
A21: 10 | B21: ="EMITTER_"&TEXT(A21,"0") -> EMITTER_10 | C21: =5*A21 -> 50 | D21: =A21*1000+E21 -> 10001 | E21: 1 | F21: Simple HOSTILE TA/TT/MG Emitter - TA displayed | G21: Z111A | H21: ACQUISITION | L21: 7000 | M21: 7200 | N21: =M21-L21 -> 200 | O21: =M21-L21 -> 200 | P21: STABLE | R21: 300 | S21: 400 | T21: =S21-R21 -> 100 | U21: STABLE | W21: 0.3 | X21: 0.4 | Y21: =X21-W21 -> 0.1 | Z21: 2 | AA21: 2 | AB21: MAU | AC21: 0 | AD21: 100 | AE21: 0 | AF21: 0 | AG21: 3 | AH21: 3 | AI21: 0 | AJ21: 0 | AK21: 0 | AL21: 100 | AM21: 25 | AN21: 0 | AO21: 0 | AP21: 0 | AQ21: 0 | AR21: 0 | AS21: 0 | AT21: 0 | AU21: 0 | AV21: 0 | AW21: 5 | AX21: 0 | AY21: 1 | AZ21: 0 | BA21: 1 | BB21: 1 | BC21: 0 | BD21: 0.9 | BE21: =2*BI21 -> 24 | BF21: 0 | BG21: 0 | BH21: 0 | BI21: 12 | BJ21: 3 | BK21: ESM/RWR | BM21: 1 | BX21: n | BY21: ="Approx "&TEXT((2*AA21),0)&" (2*SP)" -> Approx 4 (2*SP) | BZ21: Sea
A22: 10 | B22: ="EMITTER_"&TEXT(A22,"0") -> EMITTER_10 | C22: =5*A22 -> 50 | D22: =A22*1000+E22 -> 10003 | E22: 3 | F22: Simple HOSTILE TA/TT/MG Emitter - MG displayed | G22: Z113A | H22: GUIDANCE_ILLUMINATION | L22: 12000 | M22: 12010 | N22: =M22-L22 -> 10 | O22: =M22-L22 -> 10 | P22: STABLE | R22: 1550 | S22: 1580 | T22: =S22-R22 -> 30 | U22: STABLE | V22: Stable PRI with Triplets inserted between pulses. Az Cmd 3/3usec triplet, El Cmd 3/5usec triplet, in mid 80% of PRI. Both triplets in every PRI. Triplet PW 1usec. | W22: 3 | X22: 3.5 | Y22: =X22-W22 -> 0.5 | Z22: 0 | AA22: 0 | AB22: STEADY | AC22: 0 | AD22: 0 | AE22: 0 | AF22: 9999 | AG22: 3 | AH22: 3 | AI22: 0 | AJ22: 0 | AK22: 0 | AL22: 104 | AM22: 25 | AN22: 0 | AO22: 0 | AP22: 0 | AQ22: 0 | AR22: 10 | AS22: 3 | AT22: 0 | AU22: 0 | AV22: 0 | AW22: 5 | AX22: 0 | AY22: 1 | AZ22: 8 | BA22: 1 | BB22: 1 | BC22: 0 | BD22: 0.9 | BE22: =2*BI22 -> 24 | BF22: 0 | BG22: 0 | BH22: 0 | BI22: 12 | BJ22: 3 | BK22: ESM/RWR | BM22: 1 | BV22: 1 | BX22: y | BY22: 4 | BZ22: Sea
A23: 10 | B23: ="EMITTER_"&TEXT(A23,"0") -> EMITTER_10 | C23: =5*A23 -> 50 | D23: =A23*1000+E23 -> 10002 | E23: 2 | F23: Simple HOSTILE TA/TT/MG Emitter - TT displayed | G23: Z112A | H23: TRACK | L23: 15000 | M23: 15200 | N23: =M23-L23 -> 200 | O23: =M23-L23 -> 200 | P23: STABLE | R23: 300 | S23: 400 | T23: =S23-R23 -> 100 | U23: STABLE | W23: 0.3 | X23: 0.44 | Y23: =X23-W23 -> 0.14 | Z23: 0 | AA23: 0 | AB23: STEADY | AC23: 0 | AD23: 0 | AE23: 0 | AF23: 9999 | AG23: 3 | AH23: 3 | AI23: 0 | AJ23: 0 | AK23: 0 | AL23: 105 | AM23: 25 | AN23: 0 | AO23: 0 | AP23: 0 | AQ23: 0 | AR23: 10 | AS23: 3 | AT23: 0 | AU23: 0 | AV23: 0 | AW23: 5 | AX23: 0 | AY23: 1 | AZ23: 8 | BA23: 1 | BB23: 1 | BC23: 0 | BD23: 0.9 | BE23: =2*BI23 -> 24 | BF23: 0 | BG23: 0 | BH23: 0 | BI23: 12 | BJ23: 3 | BK23: ESM/RWR | BM23: 1 | BR23: 1 | BX23: y | BY23: 2 | BZ23: Sea
A24: 11 | B24: ="EMITTER_"&TEXT(A24,"0") -> EMITTER_11 | C24: =5*A24 -> 55 | D24: =A24*1000+E24 -> 11001 | E24: 1 | F24: Simple HOSTILE AAA | G24: ="Z0"&TEXT(A24,"0")&"Z" -> Z011Z | H24: SEARCH_ACQUISITION | L24: 16000 | M24: 16200 | N24: =M24-L24 -> 200 | O24: =M24-L24 -> 200 | P24: AGILE | Q24: Random Pulse to pulse agile within Freq range | R24: 200 | S24: 300 | T24: =S24-R24 -> 100 | U24: AGILE | V24: 16 posn stagger(200 289 212 299 240 253 206 300 230 277 213 250 216 288 211 287) | W24: 0.7 | X24: 0.8 | Y24: =X24-W24 -> 0.1 | Z24: 15 | AA24: 15 | AB24: MAU | AC24: 0 | AD24: 360 | AE24: 0 | AF24: 0 | AG24: 3 | AH24: 5 | AI24: 0 | AJ24: 0 | AK24: 200? | AL24: 120 | AM24: 20 | AN24: 0 | AO24: 0 | AP24: 0 | AQ24: 0 | AR24: 0 | AS24: 0 | AT24: 0 | AU24: 0 | AV24: 0 | AW24: 1 | AX24: 0 | AY24: 1 | AZ24: 0 | BA24: 1 | BB24: 0 | BC24: 1 | BD24: 0.9 | BE24: =2*BI24 -> 6 | BF24: 0 | BG24: 0 | BH24: 0 | BI24: 3 | BJ24: 3 | BK24: ESM/RWR | BM24: 1 | BV24: 1 | BX24: n | BY24: ="Approx "&TEXT((2*AA24),0)&" (2*SP)" -> Approx 30 (2*SP) | BZ24: Land
A25: 11 | B25: ="EMITTER_"&TEXT(A25,"0") -> EMITTER_11 | C25: =5*A25 -> 55 | D25: =A25*1000+E25 -> 11002 | E25: 2 | F25: Simple HOSTILE AAA | G25: ="Z0"&TEXT(A25,"0")&"Z" -> Z011Z | H25: FIRE_CONTROL | L25: 16000 | M25: 16200 | N25: =M25-L25 -> 200 | O25: =M25-L25 -> 200 | P25: AGILE | Q25: +++++--++-+-+ 13 phase shifts per pulse width evenly spaced | R25: 200 | S25: 249 | T25: =S25-R25 -> 49 | U25: AGO;E | V25: 4 PRI (200 249 211 237) Dwell for 50 pulses each) | W25: 10 | X25: 12 | Y25: =X25-W25 -> 2 | Z25: 3.6 | AA25: 3.6 | AB25: EAB | AC25: 0 | AD25: 60 | AE25: 0 | AF25: 44.85 | AG25: 3 | AH25: 4 | AI25: 3 | AJ25: 20 | AK25: 200? | AL25: 120 | AM25: 20 | AN25: 0 | AO25: 0 | AP25: 0 | AQ25: 0 | AR25: 4 | AS25: 16 | AT25: 0 | AU25: 0 | AV25: 0 | AW25: 1 | AX25: 0 | AY25: 1 | AZ25: 2 | BA25: 1 | BB25: 0 | BC25: 1 | BD25: 0.9 | BE25: =2*BI25 -> 6 | BF25: 0 | BG25: 1 | BH25: 0 | BI25: 3 | BJ25: 3 | BK25: ESM/RWR | BM25: 1 | BV25: 1 | BX25: y | BY25: ="Approx "&TEXT((3*AA25),0)&" (3*SP)" -> Approx 11 (3*SP) | BZ25: Land
A26: 12 | B26: ="EMITTER_"&TEXT(A26,"0") -> EMITTER_12 | C26: =5*A26 -> 60 | D26: =A26*1000+E26 -> 12001 | E26: 1 | F26: Simple HOSTILE S/TA Emitter | G26: Z114A | H26: ACQUISITION | L26: 2100 | M26: 2180 | N26: =M26-L26 -> 80 | O26: =M26-L26 -> 80 | P26: STABLE | R26: 100 | S26: 120 | T26: =S26-R26 -> 20 | U26: STABLE | W26: 1 | X26: 2 | Y26: =X26-W26 -> 1 | Z26: 1 | AA26: 1 | AB26: MAU | AC26: 0 | AD26: 360 | AE26: 0 | AG26: 3 | AH26: 10 | AI26: 0 | AJ26: 0 | AK26: 0 | AL26: 100 | AM26: 25 | AN26: 0 | AO26: 0 | AP26: 0 | AQ26: 0 | AR26: 0 | AS26: 0 | AT26: 0 | AU26: 0 | AV26: 0 | AW26: 1 | AX26: 0 | AY26: 1 | AZ26: 0 | BA26: 1 | BB26: 0 | BC26: 0 | BD26: 0.9 | BE26: =2*BI26 -> 20 | BF26: 0 | BG26: 0 | BH26: 0 | BI26: 10 | BJ26: 10 | BK26: ESM/RWR | BO26: 1 | BR26: 1 | BW26: Search mode, 1 of 2. T/G mode can be present at the same time. ESM to correlate to a single emitter. | BX26: n | BY26: ="Approx "&TEXT((2*AA26),0)&" (2*SP)" -> Approx 2 (2*SP) | BZ26: Sea
A27: 12 | B27: ="EMITTER_"&TEXT(A27,"0") -> EMITTER_12 | C27: =5*A27 -> 60 | D27: =A27*1000+E27 -> 12002 | E27: 2 | F27: Simple HOSTILE S/TA Emitter | G27: Z115A | H27: ACQUISITION | L27: 2180 | M27: 2190 | N27: =M27-L27 -> 10 | O27: =M27-L27 -> 10 | P27: STABLE | R27: 155 | S27: 185 | T27: =S27-R27 -> 30 | U27: STAGGER | V27: 2 Posn Stagger (155 185) | W27: 4 | X27: 4.5 | Y27: =X27-W27 -> 0.5 | Z27: 1 | AA27: 1 | AB27: MAU | AC27: 0 | AD27: 360 | AE27: 0 | AG27: 3 | AH27: 10 | AI27: 0 | AJ27: 0 | AK27: 0 | AL27: 100 | AM27: 25 | AN27: 0 | AO27: 0 | AP27: 0 | AQ27: 0 | AR27: 0 | AS27: 0 | AT27: 0 | AU27: 0 | AV27: 0 | AW27: 1 | AX27: 0 | AY27: 1 | AZ27: 0 | BA27: 1 | BB27: 0 | BC27: 0 | BD27: 0.9 | BE27: =2*BI27 -> 20 | BF27: 0 | BG27: 0 | BH27: 0 | BI27: 10 | BJ27: 10 | BK27: ESM/RWR | BM27: 1 | BR27: 1 | BX27: y | BY27: 2 | BZ27: Sea
A28: 12 | B28: ="EMITTER_"&TEXT(A28,"0") -> EMITTER_12 | C28: =5*A28 -> 60 | D28: =A28*1000+E28 -> 12001 | E28: 1 | F28: Simple HOSTILE MG Emitter - MG displayed | G28: Z116A | H28: TRACK_GUIDANCE | L28: 14511 | M28: 14741 | N28: =M28-L28 -> 230 | O28: =M28-L28 -> 230 | P28: AGILE | Q28: 4 Freq (14511 14741 14598 14633 ) Pulse to pulse Freq Agile | R28: 250 | S28: 500 | T28: =S28-R28 -> 250 | U28: AGILE | V28: Random within PRI Range | W28: 1 | X28: 4 | Y28: =X28-W28 -> 3 | Z28: 0 | AA28: 0 | AB28: MAU | AC28: 0 | AD28: 0 | AE28: 0 | AF28: 9999 | AG28: 3 | AH28: 10 | AI28: 0 | AJ28: 0 | AK28: 250 | AL28: 115 | AM28: 25 | AN28: 0 | AO28: 0 | AP28: 0 | AQ28: 0 | AR28: 0 | AS28: 0 | AT28: 0 | AU28: 0 | AV28: 0 | AW28: 1 | AX28: 0 | AY28: 1 | AZ28: 8 | BA28: 1 | BB28: 0 | BC28: 1 | BD28: 0.9 | BE28: =2*BI28 -> 20 | BF28: 0 | BG28: 0 | BH28: 0 | BI28: 10 | BJ28: 10 | BK28: ESM/RWR | BM28: 1 | BX28: n | BY28: ="Approx "&TEXT((2*AA28),0)&" (2*SP)" -> Approx 0 (2*SP) | BZ28: Sea
A29: 13 | B29: ="EMITTER_"&TEXT(A29,"0") -> EMITTER_13 | C29: =5*A29 -> 65 | D29: =A29*1000+E29 -> 13003 | E29: 3 | F29: Simple NEUTRAL HF Emitter | G29: ="Z0"&TEXT(A29,"0")&"Z" -> Z013Z | H29: HEIGHT_FINDING | L29: 2800 | M29: 2850 | N29: =M29-L29 -> 50 | O29: =M29-L29 -> 50 | P29: STABLE | R29: 1666 | S29: 2400 | T29: =S29-R29 -> 734 | U29: STAGGER | V29: 6 posn stagger (2400 1800 2140 1967 1666 1845) | W29: 2 | X29: 4 | Y29: =X29-W29 -> 2 | Z29: 1 | AA29: 1 | AB29: MAU | AC29: 0 | AD29: 0 | AE29: 0 | AF29: 0 | AG29: 2 | AH29: 1 | AI29: 0 | AJ29: 0 | AK29: 0 | AL29: 90 | AM29: 20 | AN29: 0 | AO29: 0 | AP29: 0 | AQ29: 0 | AR29: 0 | AS29: 30 | AT29: 0 | AU29: 0 | AV29: 0 | AW29: 1 | AX29: 0 | AY29: 1 | AZ29: 0 | BA29: 0 | BB29: 0 | BC29: 0 | BD29: 0.8 | BE29: 20 | BF29: 0 | BG29: 0 | BH29: 0 | BI29: NA | BJ29: 5 | BK29: ESM | BO29: 1 | BR29: 1 | BX29: n | BY29: ="Approx "&TEXT((3*AA29),0)&" (3*SP)" -> Approx 3 (3*SP) | BZ29: Land
A30: 13 | B30: ="EMITTER_"&TEXT(A30,"0") -> EMITTER_13 | C30: =5*A30 -> 65 | D30: =A30*1000+E30 -> 13002 | E30: 2 | F30: Simple NEUTRAL HF Emitter | G30: ="Z0"&TEXT(A30,"0")&"Z" -> Z013Z | H30: HEIGHT_FINDING | L30: 2900 | M30: 2950 | N30: =M30-L30 -> 50 | O30: =M30-L30 -> 50 | P30: STABLE | R30: 2020 | S30: 3000 | T30: =S30-R30 -> 980 | U30: STAGGER | V30: 3 posn stagger (3000 2020 2140) | W30: 2 | X30: 4 | Y30: =X30-W30 -> 2 | Z30: 1 | AA30: 1 | AB30: MAU | AC30: 0 | AD30: 0 | AE30: 0 | AF30: 0 | AG30: 2 | AH30: 1 | AI30: 0 | AJ30: 0 | AK30: 0 | AL30: 90 | AM30: 20 | AN30: 0 | AO30: 0 | AP30: 0 | AQ30: 0 | AR30: 0 | AS30: 30 | AT30: 0 | AU30: 0 | AV30: 0 | AW30: 1 | AX30: 0 | AY30: 1 | AZ30: 0 | BA30: 0 | BB30: 0 | BC30: 0 | BD30: 0.8 | BE30: 20 | BF30: 0 | BG30: 0 | BH30: 0 | BI30: NA | BJ30: 5 | BK30: ESM | BP30: 1 | BR30: 1 | BS30: 1 | BX30: n | BY30: ="Approx "&TEXT((3*AA30),0)&" (3*SP)" -> Approx 3 (3*SP) | BZ30: Land
A31: 13 | B31: ="EMITTER_"&TEXT(A31,"0") -> EMITTER_13 | C31: =5*A31 -> 65 | D31: =A31*1000+E31 -> 13001 | E31: 1 | F31: Simple NEUTRAL HF Emitter | G31: ="Z0"&TEXT(A31,"0")&"Z" -> Z013Z | H31: HEIGHT_FINDING | L31: 3000 | M31: 3150 | N31: =M31-L31 -> 150 | O31: =M31-L31 -> 150 | P31: STABLE | R31: 2400 | S31: 2988 | T31: =S31-R31 -> 588 | U31: STAGGER | V31: 2 posn Stagger (2400 2988) | W31: 2 | X31: 2.6 | Y31: =X31-W31 -> 0.6 | Z31: 1 | AA31: 1 | AB31: MAU | AC31: 0 | AD31: 0 | AE31: 0 | AF31: 0 | AG31: 2 | AH31: 1 | AI31: 0 | AJ31: 0 | AK31: 0 | AL31: 90 | AM31: 20 | AN31: 0 | AO31: 0 | AP31: 0 | AQ31: 0 | AR31: 0 | AS31: 30 | AT31: 0 | AU31: 0 | AV31: 0 | AW31: 1 | AX31: 0 | AY31: 1 | AZ31: 0 | BA31: 0 | BB31: 0 | BC31: 0 | BD31: 0.8 | BE31: 20 | BF31: 0 | BG31: 0 | BH31: 0 | BI31: NA | BJ31: 5 | BK31: ESM | BO31: 1 | BR31: 1 | BX31: n | BY31: ="Approx "&TEXT((3*AA31),0)&" (3*SP)" -> Approx 3 (3*SP) | BZ31: Land
A32: 14 | B32: ="EMITTER_"&TEXT(A32,"0") -> EMITTER_14 | C32: =5*A32 -> 70 | D32: =A32*1000+E32 -> 14001 | E32: 1 | F32: Simple FRIENDLY TA Emitter | G32: ="Z0"&TEXT(A32,"0")&"Z" -> Z014Z | H32: SEARCH_ACQUISITION | L32: 4500 | M32: 4550 | N32: =M32-L32 -> 50 | O32: =M32-L32 -> 50 | P32: STABLE | R32: 70 | S32: 100 | T32: =S32-R32 -> 30 | U32: STAGGER | V32: 4 Posn Stagger (70 80 90 100) | W32: 1 | X32: 3 | Y32: =X32-W32 -> 2 | Z32: 10 | AA32: 10 | AB32: MAU | AC32: 0 | AD32: 360 | AE32: 0 | AF32: 0 | AG32: 4 | AH32: 10 | AI32: 0 | AJ32: 0 | AK32: 0 | AL32: 100 | AM32: 20 | AN32: 0 | AO32: 0 | AP32: 0 | AQ32: 0 | AR32: 0 | AS32: 0 | AT32: 0 | AU32: 0 | AV32: 0 | AW32: 1 | AX32: 0 | AY32: 1 | AZ32: 0 | BA32: 1 | BB32: 0 | BC32: 1 | BD32: 0.9 | BE32: 20 | BF32: 0 | BG32: 0 | BH32: 0 | BI32: NA | BJ32: 4 | BK32: ESM/RWR | BO32: 1 | BR32: 1 | BX32: n | BY32: ="Approx "&TEXT((2*AA32),0)&" (2*SP)" -> Approx 20 (2*SP) | BZ32: Land
A33: 14 | B33: ="EMITTER_"&TEXT(A33,"0") -> EMITTER_14 | C33: =5*A33 -> 70 | D33: =A33*1000+E33 -> 14002 | E33: 2 | F33: Simple FRIENDLY TA Emitter | G33: ="Z0"&TEXT(A33,"0")&"Z" -> Z014Z | H33: SEARCH_ACQUISITION | L33: 4600 | M33: 4650 | N33: =M33-L33 -> 50 | O33: =M33-L33 -> 50 | P33: STABLE | R33: 70 | S33: 100 | T33: =S33-R33 -> 30 | U33: STAGGER | V33: 4 Posn Stagger (70 80 90 100) | W33: 1 | X33: 3 | Y33: =X33-W33 -> 2 | Z33: 10 | AA33: 10 | AB33: MAU | AC33: 0 | AD33: 360 | AE33: 0 | AF33: 0 | AG33: 4 | AH33: 10 | AI33: 0 | AJ33: 0 | AK33: 0 | AL33: 100 | AM33: 20 | AN33: 0 | AO33: 0 | AP33: 0 | AQ33: 0 | AR33: 0 | AS33: 0 | AT33: 0 | AU33: 0 | AV33: 0 | AW33: 1 | AX33: 0 | AY33: 1 | AZ33: 0 | BA33: 1 | BB33: 0 | BC33: 1 | BD33: 0.9 | BE33: 20 | BF33: 0 | BG33: 0 | BH33: 0 | BI33: NA | BJ33: 4 | BK33: ESM/RWR | BN33: 1 | BR33: 1 | BX33: n | BY33: ="Approx "&TEXT((2*AA33),0)&" (2*SP)" -> Approx 20 (2*SP) | BZ33: Land
A34: 15 | B34: ="EMITTER_"&TEXT(A34,"0") -> EMITTER_15 | C34: =5*A34 -> 75 | D34: =A34*1000+E34 -> 15001 | E34: 1 | F34: Simple HOSTILE S Emitter | G34: Z117A | H34: SEARCH_ACQUISITION | L34: 9000 | M34: 9200 | N34: =M34-L34 -> 200 | O34: =M34-L34 -> 200 | P34: STABLE | R34: 500 | S34: 800 | T34: =S34-R34 -> 300 | U34: STABLE | W34: 2 | X34: 12 | Y34: =X34-W34 -> 10 | Z34: 5 | AA34: 5 | AB34: MAU | AC34: 0 | AD34: 160 | AE34: 0 | AF34: 0 | AG34: 2 | AH34: 5 | AI34: 0 | AJ34: 0 | AK34: 0 | AL34: 100 | AM34: 20 | AN34: 0 | AO34: 0 | AP34: 0 | AQ34: 0 | AR34: 0 | AS34: 0 | AT34: 0 | AU34: 0 | AV34: 0 | AW34: 1 | AX34: 0 | AY34: 1 | AZ34: 0 | BA34: 1 | BB34: 0 | BC34: 0 | BD34: 0.9 | BE34: =2*BI34 -> 24 | BF34: 0 | BG34: 0 | BH34: 0 | BI34: 12 | BJ34: 5 | BK34: ESM/RWR | BM34: 1 | BW34: Search mode,T/G mode and MG mode can be present at the same time. ESM to correlate to a single emitter. | BX34: n | BY34: ="Approx "&TEXT((2*AA34),0)&" (2*SP)" -> Approx 10 (2*SP) | BZ34: Sea
A35: 15 | B35: ="EMITTER_"&TEXT(A35,"0") -> EMITTER_15 | C35: =5*A35 -> 75 | D35: =A35*1000+E35 -> 15002 | E35: 2 | F35: Simple HOSTILE T/G Emitter | G35: Z118A | H35: TRACK_GUIDANCE | L35: 10600 | M35: 10800 | N35: =M35-L35 -> 200 | O35: =M35-L35 -> 200 | P35: STABLE | R35: 60 | S35: 66 | T35: =S35-R35 -> 6 | U35: STABLE | W35: 4 | X35: 4.5 | Y35: =X35-W35 -> 0.5 | Z35: 0 | AA35: 0 | AB35: STEADY | AC35: 0 | AD35: 0 | AE35: 0 | AF35: 9999 | AG35: 2 | AH35: 5 | AI35: 0 | AJ35: 0 | AK35: 0 | AL35: 100 | AM35: 20 | AN35: 0 | AO35: 0 | AP35: 0 | AQ35: 0 | AR35: 0 | AS35: 0 | AT35: 0 | AU35: 0 | AV35: 0 | AW35: 1 | AX35: 0 | AY35: 1 | AZ35: 8 | BA35: 1 | BB35: 0 | BC35: 0 | BD35: 0.9 | BE35: =2*BI35 -> 24 | BF35: 0 | BG35: 0 | BH35: 0 | BI35: 12 | BJ35: 5 | BK35: ESM/RWR | BM35: 1 | BX35: y | BY35: 2 | BZ35: Sea
A36: 15 | B36: ="EMITTER_"&TEXT(A36,"0") -> EMITTER_15 | C36: =5*A36 -> 75 | D36: =A36*1000+E36 -> 15003 | E36: 3 | F36: Simple HOSTILE MG Emitter | G36: Z119A | H36: GUIDANCE_ILLUMINATION | L36: 13500 | M36: 13700 | N36: =M36-L36 -> 200 | O36: =M36-L36 -> 200 | P36: STABLE | R36: 5 | S36: 8 | T36: =S36-R36 -> 3 | U36: AGILE | V36: Random within PRI Range | W36: 2 | X36: 2.6 | Y36: =X36-W36 -> 0.6 | Z36: 0 | AA36: 0 | AB36: STEADY | AC36: 0 | AD36: 0 | AE36: 0 | AF36: 9999 | AG36: 2 | AH36: 5 | AI36: 0 | AJ36: 0 | AK36: 0 | AL36: 100 | AM36: 20 | AN36: 0 | AO36: 0 | AP36: 0 | AQ36: 0 | AR36: 0 | AS36: 0 | AT36: 0 | AU36: 0 | AV36: 0 | AW36: 1 | AX36: 0 | AY36: 1 | AZ36: 8 | BA36: 1 | BB36: 0 | BC36: 0 | BD36: 0.9 | BE36: =2*BI36 -> 24 | BF36: 0 | BG36: 0 | BH36: 0 | BI36: 12 | BJ36: 5 | BK36: ESM/RWR | BM36: 1 | BX36: y | BY36: 2 | BZ36: Sea
A37: 16 | B37: ="EMITTER_"&TEXT(A37,"0") -> EMITTER_16 | C37: =5*A37 -> 80 | D37: =A37*1000+E37 -> 16001 | E37: 1 | F37: Simple HOSTILE S Emitter TA | G37: ="Z0"&TEXT(A37,"0")&"Z" -> Z016Z | H37: SEARCH_ACQUISITION | L37: 28100 | M37: 28300 | N37: 200 | O37: =M37-L37 -> 200 | P37: AGILE | Q37: Random Pulse to pulse agile within Freq range | R37: 100 | S37: 500 | T37: =S37-R37 -> 400 | U37: STABLE | W37: 2 | X37: 3 | Y37: =X37-W37 -> 1 | Z37: 4 | AA37: 4 | AB37: MAU | AC37: 0 | AD37: 360 | AE37: 0 | AF37: 0 | AG37: 2 | AH37: 10 | AI37: 0 | AJ37: 0 | AK37: 200? | AL37: 120 | AM37: 25 | AN37: 0 | AO37: 0 | AP37: 0 | AQ37: 0 | AR37: 0 | AS37: 0 | AT37: 0 | AU37: 0 | AV37: 0 | AW37: 1 | AX37: 0 | AY37: 1 | AZ37: 0 | BA37: 0 | BB37: 0 | BC37: 0 | BD37: 0.8 | BE37: 20 | BF37: 0 | BG37: 0 | BH37: 0 | BI37: NA | BJ37: 2 | BK37: ESM/RWR | BM37: 1 | BX37: n | BY37: ="Approx "&TEXT((2*AA37),0)&" (2*SP)" -> Approx 8 (2*SP) | BZ37: Land
A38: 16 | B38: ="EMITTER_"&TEXT(A38,"0") -> EMITTER_16 | C38: =5*A38 -> 80 | D38: =A38*1000+E38 -> 16002 | E38: 2 | F38: Simple HOSTILE S Emitter TA | G38: ="Z0"&TEXT(A38,"0")&"Z" -> Z016Z | H38: SEARCH_ACQUISITION | L38: 28100 | M38: 28300 | N38: 200 | O38: =M38-L38 -> 200 | P38: STABLE | R38: 100 | S38: 500 | T38: =S38-R38 -> 400 | U38: AGILE | V38: Stable PRI with Doublets inserted between pulses. 10usec doublet each PRI | W38: 2 | X38: 3 | Y38: =X38-W38 -> 1 | Z38: 4 | AA38: 4 | AB38: MAU | AC38: 0 | AD38: 360 | AE38: 0 | AF38: 0 | AG38: 2 | AH38: 10 | AI38: 0 | AJ38: 0 | AK38: 0 | AL38: 120 | AM38: 25 | AN38: 0 | AO38: 0 | AP38: 0 | AQ38: 0 | AR38: 0 | AS38: 0 | AT38: 0 | AU38: 0 | AV38: 0 | AW38: 1 | AX38: 0 | AY38: 1 | AZ38: 0 | BA38: 0 | BB38: 0 | BC38: 0 | BD38: 0.8 | BE38: 20 | BF38: 0 | BG38: 0 | BH38: 0 | BI38: NA | BJ38: 2 | BK38: ESM/RWR | BM38: 1 | BX38: n | BY38: ="Approx "&TEXT((2*AA38),0)&" (2*SP)" -> Approx 8 (2*SP) | BZ38: Land
A39: 16 | B39: ="EMITTER_"&TEXT(A39,"0") -> EMITTER_16 | C39: =5*A39 -> 80 | D39: =A39*1000+E39 -> 16003 | E39: 3 | F39: Simple HOSTILE S Emitter TA | G39: ="Z0"&TEXT(A39,"0")&"Z" -> Z016Z | H39: SEARCH_ACQUISITION | L39: 28100 | M39: 28300 | N39: 200 | O39: =M39-L39 -> 200 | P39: STABLE | R39: 100 | S39: 500 | T39: =S39-R39 -> 400 | U39: AGILE | V39: Stable PRI with Triplets inserted between pulses. 10/15usec triplet each PRI. | W39: 2 | X39: 3 | Y39: =X39-W39 -> 1 | Z39: 4 | AA39: 4 | AB39: MAU | AC39: 0 | AD39: 360 | AE39: 0 | AF39: 0 | AG39: 2 | AH39: 10 | AI39: 0 | AJ39: 0 | AK39: 0 | AL39: 120 | AM39: 25 | AN39: 0 | AO39: 0 | AP39: 0 | AQ39: 0 | AR39: 0 | AS39: 0 | AT39: 0 | AU39: 0 | AV39: 0 | AW39: 1 | AX39: 0 | AY39: 1 | AZ39: 0 | BA39: 0 | BB39: 0 | BC39: 0 | BD39: 0.8 | BE39: 20 | BF39: 0 | BG39: 0 | BH39: 0 | BI39: NA | BJ39: 2 | BK39: ESM/RWR | BM39: 1 | BX39: n | BY39: ="Approx "&TEXT((2*AA39),0)&" (2*SP)" -> Approx 8 (2*SP) | BZ39: Land
A40: 16 | B40: ="EMITTER_"&TEXT(A40,"0") -> EMITTER_16 | C40: =5*A40 -> 80 | D40: =A40*1000+E40 -> 16004 | E40: 4 | F40: Simple HOSTILE S Emitter TA | G40: ="Z0"&TEXT(A40,"0")&"Z" -> Z016Z | H40: SEARCH_ACQUISITION | L40: 28100 | M40: 28300 | N40: 200 | O40: =M40-L40 -> 200 | P40: AGILE | Q40: Random Pulse to pulse agile within Freq range | R40: 350 | S40: 475 | T40: =S40-R40 -> 125 | U40: STAGGER | V40: 2 Posn Stagger (350 475) | W40: 2 | X40: 3 | Y40: =X40-W40 -> 1 | Z40: 4 | AA40: 4 | AB40: MAU | AC40: 0 | AD40: 360 | AE40: 0 | AF40: 0 | AG40: 2 | AH40: 10 | AI40: 0 | AJ40: 0 | AK40: 200? | AL40: 120 | AM40: 25 | AN40: 0 | AO40: 0 | AP40: 0 | AQ40: 0 | AR40: 0 | AS40: 0 | AT40: 0 | AU40: 0 | AV40: 0 | AW40: 1 | AX40: 0 | AY40: 1 | AZ40: 0 | BA40: 0 | BB40: 0 | BC40: 0 | BD40: 0.8 | BE40: 20 | BF40: 0 | BG40: 0 | BH40: 0 | BI40: NA | BJ40: 2 | BK40: ESM/RWR | BM40: 1 | BX40: n | BY40: ="Approx "&TEXT((2*AA40),0)&" (2*SP)" -> Approx 8 (2*SP) | BZ40: Land
...

Sheet Plot Data Sheet
A1: ='MHP Emulator Emitter List'!B1 -> EMITTER_NAME | B1: Freq_Range(MHz) | C1: PRI_Range(usec) | D1: PW_Range(usec)
A2: ='MHP Emulator Emitter List'!B2 -> EMITTER_01 | B2: ='MHP Emulator Emitter List'!M2-'MHP Emulator Emitter List'!L2 -> 100 | C2: ='MHP Emulator Emitter List'!S2-'MHP Emulator Emitter List'!R2 -> 0 | D2: ='MHP Emulator Emitter List'!X2-'MHP Emulator Emitter List'!W2 -> 0
A3: ='MHP Emulator Emitter List'!B5 -> EMITTER_02 | B3: ='MHP Emulator Emitter List'!M5-'MHP Emulator Emitter List'!L5 -> 100 | C3: ='MHP Emulator Emitter List'!S5-'MHP Emulator Emitter List'!R5 -> 20 | D3: ='MHP Emulator Emitter List'!X5-'MHP Emulator Emitter List'!W5 -> 1
A4: ='MHP Emulator Emitter List'!B7 -> EMITTER_03 | B4: ='MHP Emulator Emitter List'!M7-'MHP Emulator Emitter List'!L7 -> 50 | C4: ='MHP Emulator Emitter List'!S7-'MHP Emulator Emitter List'!R7 -> 30 | D4: ='MHP Emulator Emitter List'!X7-'MHP Emulator Emitter List'!W7 -> 1
A5: ='MHP Emulator Emitter List'!B8 -> EMITTER_03 | B5: ='MHP Emulator Emitter List'!M8-'MHP Emulator Emitter List'!L8 -> 50 | C5: ='MHP Emulator Emitter List'!S8-'MHP Emulator Emitter List'!R8 -> 63 | D5: ='MHP Emulator Emitter List'!X8-'MHP Emulator Emitter List'!W8 -> 4
A6: ='MHP Emulator Emitter List'!B9 -> EMITTER_04 | B6: ='MHP Emulator Emitter List'!M9-'MHP Emulator Emitter List'!L9 -> 50 | C6: ='MHP Emulator Emitter List'!S9-'MHP Emulator Emitter List'!R9 -> 400 | D6: ='MHP Emulator Emitter List'!X9-'MHP Emulator Emitter List'!W9 -> 2
A7: ='MHP Emulator Emitter List'!B14 -> EMITTER_07 | B7: ='MHP Emulator Emitter List'!M14-'MHP Emulator Emitter List'!L14 -> 50 | C7: ='MHP Emulator Emitter List'!S14-'MHP Emulator Emitter List'!R14 -> 0 | D7: ='MHP Emulator Emitter List'!X14-'MHP Emulator Emitter List'!W14 -> 0
A8: ='MHP Emulator Emitter List'!B15 -> EMITTER_08 | B8: ='MHP Emulator Emitter List'!M15-'MHP Emulator Emitter List'!L15 -> 200 | C8: ='MHP Emulator Emitter List'!S15-'MHP Emulator Emitter List'!R15 -> 60 | D8: ='MHP Emulator Emitter List'!X15-'MHP Emulator Emitter List'!W15 -> 3
A9: ='MHP Emulator Emitter List'!B17 -> EMITTER_08 | B9: ='MHP Emulator Emitter List'!M17-'MHP Emulator Emitter List'!L17 -> 90 | C9: ='MHP Emulator Emitter List'!S17-'MHP Emulator Emitter List'!R17 -> 60 | D9: ='MHP Emulator Emitter List'!X17-'MHP Emulator Emitter List'!W17 -> 3
A10: ='MHP Emulator Emitter List'!B19 -> EMITTER_09 | B10: ='MHP Emulator Emitter List'!M19-'MHP Emulator Emitter List'!L19 -> 500 | C10: ='MHP Emulator Emitter List'!S19-'MHP Emulator Emitter List'!R19 -> 11 | D10: ='MHP Emulator Emitter List'!X19-'MHP Emulator Emitter List'!W19 -> 4
A11: ='MHP Emulator Emitter List'!B20 -> EMITTER_09 | B11: ='MHP Emulator Emitter List'!M20-'MHP Emulator Emitter List'!L20 -> 240 | C11: ='MHP Emulator Emitter List'!S20-'MHP Emulator Emitter List'!R20 -> 10 | D11: ='MHP Emulator Emitter List'!X20-'MHP Emulator Emitter List'!W20 -> 1
A12: ='MHP Emulator Emitter List'!B24 -> EMITTER_11 | B12: ='MHP Emulator Emitter List'!M24-'MHP Emulator Emitter List'!L24 -> 200 | C12: ='MHP Emulator Emitter List'!S24-'MHP Emulator Emitter List'!R24 -> 100 | D12: ='MHP Emulator Emitter List'!X24-'MHP Emulator Emitter List'!W24 -> 0.1
A13: ='MHP Emulator Emitter List'!B26 -> EMITTER_12 | B13: ='MHP Emulator Emitter List'!M26-'MHP Emulator Emitter List'!L26 -> 80 | C13: ='MHP Emulator Emitter List'!S26-'MHP Emulator Emitter List'!R26 -> 20 | D13: ='MHP Emulator Emitter List'!X26-'MHP Emulator Emitter List'!W26 -> 1
A14: ='MHP Emulator Emitter List'!B27 -> EMITTER_12 | B14: ='MHP Emulator Emitter List'!M27-'MHP Emulator Emitter List'!L27 -> 10 | C14: ='MHP Emulator Emitter List'!S27-'MHP Emulator Emitter List'!R27 -> 30 | D14: ='MHP Emulator Emitter List'!X27-'MHP Emulator Emitter List'!W27 -> 0.5
A15: ='MHP Emulator Emitter List'!B28 -> EMITTER_12 | B15: ='MHP Emulator Emitter List'!M28-'MHP Emulator Emitter List'!L28 -> 230 | C15: ='MHP Emulator Emitter List'!S28-'MHP Emulator Emitter List'!R28 -> 250 | D15: ='MHP Emulator Emitter List'!X28-'MHP Emulator Emitter List'!W28 -> 3
A16: ='MHP Emulator Emitter List'!B29 -> EMITTER_13 | B16: ='MHP Emulator Emitter List'!M29-'MHP Emulator Emitter List'!L29 -> 50 | C16: ='MHP Emulator Emitter List'!S29-'MHP Emulator Emitter List'!R29 -> 734 | D16: ='MHP Emulator Emitter List'!X29-'MHP Emulator Emitter List'!W29 -> 2
A17: ='MHP Emulator Emitter List'!B30 -> EMITTER_13 | B17: ='MHP Emulator Emitter List'!M30-'MHP Emulator Emitter List'!L30 -> 50 | C17: ='MHP Emulator Emitter List'!S30-'MHP Emulator Emitter List'!R30 -> 980 | D17: ='MHP Emulator Emitter List'!X30-'MHP Emulator Emitter List'!W30 -> 2
A18: ='MHP Emulator Emitter List'!B31 -> EMITTER_13 | B18: ='MHP Emulator Emitter List'!M31-'MHP Emulator Emitter List'!L31 -> 150 | C18: ='MHP Emulator Emitter List'!S31-'MHP Emulator Emitter List'!R31 -> 588 | D18: ='MHP Emulator Emitter List'!X31-'MHP Emulator Emitter List'!W31 -> 0.6
A19: ='MHP Emulator Emitter List'!B32 -> EMITTER_14 | B19: ='MHP Emulator Emitter List'!M32-'MHP Emulator Emitter List'!L32 -> 50 | C19: ='MHP Emulator Emitter List'!S32-'MHP Emulator Emitter List'!R32 -> 30 | D19: ='MHP Emulator Emitter List'!X32-'MHP Emulator Emitter List'!W32 -> 2
A20: ='MHP Emulator Emitter List'!#REF! -> #REF! | B20: ='MHP Emulator Emitter List'!#REF!-'MHP Emulator Emitter List'!#REF! -> #REF! | C20: ='MHP Emulator Emitter List'!#REF!-'MHP Emulator Emitter List'!#REF! -> #REF! | D20: ='MHP Emulator Emitter List'!#REF!-'MHP Emulator Emitter List'!#REF! -> #REF!
A21: ='MHP Emulator Emitter List'!B37 -> EMITTER_16 | B21: ='MHP Emulator Emitter List'!M37-'MHP Emulator Emitter List'!L37 -> 200 | C21: ='MHP Emulator Emitter List'!S37-'MHP Emulator Emitter List'!R37 -> 400 | D21: ='MHP Emulator Emitter List'!X37-'MHP Emulator Emitter List'!W37 -> 1
A22: ='MHP Emulator Emitter List'!B41 -> EMITTER_17 | B22: ='MHP Emulator Emitter List'!M41-'MHP Emulator Emitter List'!L41 -> 200 | C22: ='MHP Emulator Emitter List'!S41-'MHP Emulator Emitter List'!R41 -> 37 | D22: ='MHP Emulator Emitter List'!X41-'MHP Emulator Emitter List'!W41 -> 1
A23: ='MHP Emulator Emitter List'!B42 -> EMITTER_18 | B23: ='MHP Emulator Emitter List'!M42-'MHP Emulator Emitter List'!L42 -> 500 | C23: ='MHP Emulator Emitter List'!S42-'MHP Emulator Emitter List'!R42 -> 600 | D23: ='MHP Emulator Emitter List'!X42-'MHP Emulator Emitter List'!W42 -> 10
A26: ='MHP Emulator Emitter List'!B44 -> EMITTER_18 | B26: ='MHP Emulator Emitter List'!M44-'MHP Emulator Emitter List'!L44 -> 500 | C26: ='MHP Emulator Emitter List'!S44-'MHP Emulator Emitter List'!R44 -> 0.5 | D26: ='MHP Emulator Emitter List'!X44-'MHP Emulator Emitter List'!W44 -> 0.2
A27: ='MHP Emulator Emitter List'!B45 -> EMITTER_19 | B27: ='MHP Emulator Emitter List'!M45-'MHP Emulator Emitter List'!L45 -> 50 | C27: ='MHP Emulator Emitter List'!S45-'MHP Emulator Emitter List'!R45 -> 525 | D27: ='MHP Emulator Emitter List'!X45-'MHP Emulator Emitter List'!W45 -> 2
A28: ='MHP Emulator Emitter List'!B46 -> EMITTER_19 | B28: ='MHP Emulator Emitter List'!M46-'MHP Emulator Emitter List'!L46 -> 30 | C28: ='MHP Emulator Emitter List'!S46-'MHP Emulator Emitter List'!R46 -> 525 | D28: ='MHP Emulator Emitter List'!X46-'MHP Emulator Emitter List'!W46 -> 2
A29: ='MHP Emulator Emitter List'!B47 -> EMITTER_20 | B29: ='MHP Emulator Emitter List'!M47-'MHP Emulator Emitter List'!L47 -> 167 | C29: ='MHP Emulator Emitter List'!S47-'MHP Emulator Emitter List'!R47 -> 50 | D29: ='MHP Emulator Emitter List'!X47-'MHP Emulator Emitter List'!W47 -> 0.1
A30: ='MHP Emulator Emitter List'!B48 -> EMITTER_21 | B30: ='MHP Emulator Emitter List'!M48-'MHP Emulator Emitter List'!L48 -> 200 | C30: ='MHP Emulator Emitter List'!S48-'MHP Emulator Emitter List'!R48 -> 55 | D30: ='MHP Emulator Emitter List'!X48-'MHP Emulator Emitter List'!W48 -> 0.1
A31: ='MHP Emulator Emitter List'!B49 -> EMITTER_21 | B31: ='MHP Emulator Emitter List'!M49-'MHP Emulator Emitter List'!L49 -> 200 | C31: ='MHP Emulator Emitter List'!S49-'MHP Emulator Emitter List'!R49 -> 29 | D31: ='MHP Emulator Emitter List'!X49-'MHP Emulator Emitter List'!W49 -> 1
A32: ='MHP Emulator Emitter List'!B50 -> EMITTER_22 | B32: ='MHP Emulator Emitter List'!M50-'MHP Emulator Emitter List'!L50 -> 100 | C32: ='MHP Emulator Emitter List'!S50-'MHP Emulator Emitter List'!R50 -> 50 | D32: ='MHP Emulator Emitter List'!X50-'MHP Emulator Emitter List'!W50 -> 2
A33: ='MHP Emulator Emitter List'!B52 -> EMITTER_22 | B33: ='MHP Emulator Emitter List'!M52-'MHP Emulator Emitter List'!L52 -> 100 | C33: ='MHP Emulator Emitter List'!S52-'MHP Emulator Emitter List'!R52 -> 15 | D33: ='MHP Emulator Emitter List'!X52-'MHP Emulator Emitter List'!W52 -> 12
A34: ='MHP Emulator Emitter List'!#REF! -> #REF! | B34: ='MHP Emulator Emitter List'!#REF!-'MHP Emulator Emitter List'!#REF! -> #REF! | C34: ='MHP Emulator Emitter List'!#REF!-'MHP Emulator Emitter List'!#REF! -> #REF! | D34: ='MHP Emulator Emitter List'!#REF!-'MHP Emulator Emitter List'!#REF! -> #REF!
A35: ='MHP Emulator Emitter List'!B56 -> EMITTER_25 | B35: ='MHP Emulator Emitter List'!M56-'MHP Emulator Emitter List'!L56 -> 2 | C35: ='MHP Emulator Emitter List'!S56-'MHP Emulator Emitter List'!R56 -> 0 | D35: ='MHP Emulator Emitter List'!X56-'MHP Emulator Emitter List'!W56 -> 1
A36: ='MHP Emulator Emitter List'!B57 -> EMITTER_25 | B36: ='MHP Emulator Emitter List'!M57-'MHP Emulator Emitter List'!L57 -> 2 | C36: ='MHP Emulator Emitter List'!S57-'MHP Emulator Emitter List'!R57 -> 0 | D36: ='MHP Emulator Emitter List'!X57-'MHP Emulator Emitter List'!W57 -> 2
A37: ='MHP Emulator Emitter List'!B58 -> EMITTER_25 | B37: ='MHP Emulator Emitter List'!M58-'MHP Emulator Emitter List'!L58 -> 2 | C37: ='MHP Emulator Emitter List'!S58-'MHP Emulator Emitter List'!R58 -> 0 | D37: ='MHP Emulator Emitter List'!X58-'MHP Emulator Emitter List'!W58 -> 2
A38: ='MHP Emulator Emitter List'!#REF! -> #REF! | B38: ='MHP Emulator Emitter List'!#REF!-'MHP Emulator Emitter List'!#REF! -> #REF! | C38: ='MHP Emulator Emitter List'!#REF!-'MHP Emulator Emitter List'!#REF! -> #REF! | D38: ='MHP Emulator Emitter List'!#REF!-'MHP Emulator Emitter List'!#REF! -> #REF!
A39: ='MHP Emulator Emitter List'!B63 -> EMITTER_27 | B39: ='MHP Emulator Emitter List'!M63-'MHP Emulator Emitter List'!L63 -> 0 | C39: ='MHP Emulator Emitter List'!S63-'MHP Emulator Emitter List'!R63 -> 0 | D39: ='MHP Emulator Emitter List'!X63-'MHP Emulator Emitter List'!W63 -> 3.6
A40: ='MHP Emulator Emitter List'!B65 -> EMITTER_27 | B40: ='MHP Emulator Emitter List'!M65-'MHP Emulator Emitter List'!L65 -> 50 | C40: ='MHP Emulator Emitter List'!S65-'MHP Emulator Emitter List'!R65 -> 0 | D40: ='MHP Emulator Emitter List'!X65-'MHP Emulator Emitter List'!W65 -> 3
A41: ='MHP Emulator Emitter List'!B67 -> EMITTER_28 | B41: ='MHP Emulator Emitter List'!M67-'MHP Emulator Emitter List'!L67 -> 220 | C41: ='MHP Emulator Emitter List'!S67-'MHP Emulator Emitter List'!R67 -> 200 | D41: ='MHP Emulator Emitter List'!X67-'MHP Emulator Emitter List'!W67 -> 1
A42: ='MHP Emulator Emitter List'!B70 -> EMITTER_30 | B42: ='MHP Emulator Emitter List'!M70-'MHP Emulator Emitter List'!L70 -> 100 | C42: ='MHP Emulator Emitter List'!S70-'MHP Emulator Emitter List'!R70 -> 49 | D42: ='MHP Emulator Emitter List'!X70-'MHP Emulator Emitter List'!W70 -> 2
...

Sheet Parameter Description
A1: MDF Variable | B1: Description
A2: Index | B2: The number (sequential) of the emitter in the MDF.
A3: EMITTER/NATO NAME | B3: The NATO name for the emitter. For the Unclassified Libraries the Emitter name is represented by Emitter_Index, where Index is the value listed in th first column.
A4: EID | B4: Emitter Identification. The unique emitter ID of the MDF entry. In the unclassified libraries this is simply a unique number. For the classfied libraries a List of EIDs will be determined by CFAWC EWOS.
A5: Amb EID | B5: A list of EIDs that are ambiguous with the emitter. If the row is blank, there is no ambiguity.
A6: Mode | B6: The emitter will contain 1 or more modes. This value indicates the mode of the specific entry.
A7: DESCRIPTION | B7: Describes the Hostility and the function of the specific emitter entry. The Hostility valus are given in Table 3-2, and the function values given in table 3-3.
A8: ELNOT | B8: Electronic Intelligence Notation. This is a unique identifier assigned to each emitter. For the unclassifed libraries, these values are made up. For classified libraries the ELNOT would be determined from the Electronic Warfare Integrated Reprogramming (EWIR) database.
A9: Highest_Active_Function | B9: Indicates the function of the specific emitter mode. The range of values is described in table 3-3.
A10: Threat Display | B10: The Symbol used to represent the emitter on the SDS Display
A11: Threat Priority | B11: The overall priority of the Emitter
A12: Threat Tone | B12: The tone generated when the Threat is detected.
... A25: Scan_Pattern | B25: Scan Pattern. Scan Pattern values are listed in table 3-6.
A26: Dead Time x.xx
A27: Az Sector Width xxx.x
A28: Az Slew Rate x.xxxxx
A29: TIMB xxxx.x
A30: Az BW xx.x
A31: El BW xx.x
A32: Az Bar step xx.x
A33: Num Az Pos xxx.x
A34: Signal BW xxx.x
A35: ERP (dBm) | B35: Emitter Radiated Power (dBm)
A36: Ant Gain xx.x | B36: Antenna Gain
A37: 1st dwn xx.x
A38: 1st Az Lobe Pos xxx.x
A39: 2nd dwn xx.x
A40: 2nd Az Lobe Pos xxx.x
A41: Num EL Pos xxx
A42: El Sector Width xxx.x
A43: El Slew Rate x.xxxxx
A44: 1st Lobe Pos xxx.x
A45: 2nd Lobe Pos xxx.x
A46: Ant Pol x | B46: Antenna Polarization. Polarization values are listed in table 3-7.
A47: AI x | B47: Airborne Interceptor (0=no, 1= yes)
A48: Sq or Hex? x | B48: Antenna Pattern (
A49: Scan Type x | B49: Scan Type. The Scan Type values are listed in table 3-8.
A50: Locate? x | B50: Location Candidate (0=no, 1=yes)
A51: MF x | B51: MultiBeam Emitter (0=no, 1=yes)
A52: RF Agile x | B52: Radio Frequency Agility (0=no, 1=yes)
...

Sheet Freq Coverage

Sheet Sheet2
